Workbook

Sheet Cover
B2: Spectris plc take-private by KKR
B3: LBO rebuild from the offer and financing documents
B4: Leire Novo Huerta | October 2026
B6: Question: KKR beat Advent with a £41.75 per share offer, 105% above the undisturbed price and 20.3x FY2024 EBITDA. What did KKR need to believe to pay that, and what did winning cost in returns?
B9: Key outputs (live)
B10: Entry enterprise value (£m) | C10: ='Sources & Uses'!C22 -> 4822.25
B11: EV / FY2024 EBITDA | C11: ='Sources & Uses'!C23 -> 20.176778
B12: EV / 2025E EBITDA | C12: ='Sources & Uses'!C24 -> 19.095591
B13: Term debt / FY2024 EBITDA | C13: ='Sources & Uses'!C25 -> 6.3593799
B14: Sponsor equity (£m) | C14: ='Sources & Uses'!C16 -> 3436.7924
B15: Money multiple | C15: =Returns!C13 -> 1.9760805
B16: IRR (5-year hold) | C16: =Returns!C14 -> 0.14593749
B17: Walk-away price at target IRR | C17: =Returns!C33 -> 37.118898
B18: Exit multiple needed for target IRR | C18: =Returns!C31 -> 20.533824
B19: IRR cost of beating Advent's first offer | C19: ='Bid Comparison'!J11 -> 0.02999683
B20: Model checks | C20: =Checks!D16 -> ALL OK
B22: Contents
B23: Inputs | D23: Every assumption, labelled disclosed or estimate, with its source
B24: Historicals | D24: Divisional FY2023-FY2024, H1 2024-H1 2025 and the 2025E bridge
B25: Operating Model | D25: Scientific and Dynamics sales and margins, EBITDA and free cash flow to 2030E
B26: Sources & Uses | D26: Funding at completion, fee build from the fee letter, entry metrics, equity reconciliation
B27: Debt Schedule | D27: Euro and dollar term loans, amortisation, cash sweep, credit statistics
B28: Returns | D28: Exit valuation, IRR, value creation bridge, hurdle analysis
B29: Bid Comparison | D29: Returns at each bid; Advent and KKR financing structures
B30: Comparables | D30: Trading comparables and precedent transactions behind the exit multiple
B31: Sensitivities | D31: IRR grids: price x exit multiple; divisional margins
B32: Financing Terms | D32: What the commitment letter, fee letter and announcements say
B33: Checks | D33: Integrity checks
B35: Colour code
B36: Blue text | D36: Hard-coded input
B37: Black text | D37: Formula
B38: Green text | D38: Link to another sheet
B39: Yellow fill | D39: Key judgement to stress-test
B40: Purple italic | D40: Pasted output from model runs
B42: Independent analysis built only from public offer documents, financing documents published under Rule 26, Spectris results and market data. Not KKR's model; no private information used. Items marked Estimate are assumptions.

Sheet Inputs
B2: Inputs and assumptions
B3: Blue = hard-coded input. Yellow fill = key judgement to stress. Type: Disclosed (from a deal or company document) or Estimate. Every input is a named cell.
B5: Input | C5: Value | D5: Unit | E5: Type | F5: Source or rationale
B6: Offer and share capital
B7: Offer value per share (cash + interim dividend) | C7: 41.75 | D7: £ | E7: Disclosed | F7: Increased KKR offer, 5 Aug 2025: £41.47 cash + 28p interim dividend
B8: Interim dividend per share (paid by Spectris) | C8: 0.28 | D8: £ | E8: Disclosed | F8: Same announcement; paid from company cash before completion
B9: Fully diluted shares | C9: 100.6 | D9: m | E9: Disclosed | F9: Derived: disclosed equity value ~£4.2bn ÷ £41.75. H1 2025: 99.0m weighted shares, 99.8m diluted, plus share plan awards
B10: Undisturbed share price, 6 Jun 2025 | C10: 20.38 | D10: £ | E10: Disclosed | F10: KKR increased offer announcement (premium calculation)
B11: FY2024 adjusted EBITDA used in the offer multiples | C11: 239 | D11: £m | E11: Disclosed | F11: Rule 2.7 announcement: £239m adjusted EBITDA, £203m adjusted EBIT; KKR offer = 20.3x
B12: Balance sheet at close
B13: Net debt, 30 Jun 2025 (excl. leases) | C13: 545.7 | D13: £m | E13: Disclosed | F13: H1 2025 results: gross borrowings £633.1m less cash £87.4m
B14: Spectris gross borrowings refinanced at completion | C14: 633.1 | D14: £m | E14: Disclosed | F14: H1 2025 results; existing facilities repaid on change of control
B15: Spectris cash retained on balance sheet at close | C15: 59.2 | D15: £m | E15: Estimate | F15: June cash £87.4m less ~£28m interim dividend
B16: Lease liabilities (debt-like, held flat) | C16: 76.5 | D16: £m | E16: Disclosed | F16: H1 2025: £18.3m current + £58.2m non-current. In EV at entry and deducted at exit
B17: Transaction costs
B18: Arrangement/underwriting fee, euro term loan | C18: 0.0175 | D18: % | E18: Disclosed | F18: KKR senior fee letter (TLB): 1.75% of non-USD term commitments
B19: Arrangement/underwriting fee, dollar term loan | C19: 0.0225 | D19: % | E19: Disclosed | F19: KKR senior fee letter (TLB): 2.25% of USD term commitments
B20: Original issue discount, term loans | C20: 0.01 | D20: % | E20: Disclosed | F20: KKR senior fee letter (TLB): 1.00% of term commitments (before any market flex)
B21: Revolving facility fee | C21: 0.0175 | D21: % | E21: Disclosed | F21: KKR senior fee letter: 1.75% of revolving commitments
B22: Stamp duty on shares acquired | C22: 0.005 | D22: % | E22: Estimate | F22: UK stamp duty 0.5% on a transfer scheme of arrangement
B23: Bidco advisory, legal and other deal costs | C23: 45 | D23: £m | E23: Estimate | F23: Not disclosed; ~0.9% of EV, in line with large UK take-privates
B24: Spectris transaction costs settled at close | C24: 35 | D24: £m | E24: Estimate | F24: Five advisers on the target side (GS, BofA, Rothschild, Barclays, JPM consent letters); not disclosed
B25: Debt package and pricing
B26: Euro term loan B | C26: 975 | D26: €m | E26: Disclosed | F26: Senior facilities agreement, 30 Sep 2025
B27: Dollar term loan B | C27: 900 | D27: $m | E27: Disclosed | F27: Senior facilities agreement, 30 Sep 2025
B28: Revolving credit facility (undrawn at close) | C28: 325 | D28: £m | E28: Disclosed | F28: £300m in SFA, increased to £325m when HSBC UK acceded, 14 Nov 2025
B29: EUR to GBP rate | C29: 0.87 | D29: x | E29: Estimate | F29: Approximate rate at signing; held flat
B30: GBP to USD rate | C30: 1.34 | D30: x | E30: Estimate | F30: Approximate rate at signing; held flat
B31: Term loan margin over Euribor / SOFR | C31: 0.0375 | D31: % | E31: Disclosed | F31: KKR commitment letter term sheet: Facility B 3.75%, ratchet to 3.00% at <=4.00x. Final syndicated pricing not public
B32: 3-month Euribor (average over hold) | C32: 0.02 | D32: % | E32: Estimate | F32: Market level late 2025; 0% floor per term sheet
B33: Term SOFR (average over hold) | C33: 0.036 | D33: % | E33: Estimate | F33: Market level late 2025; 0% floor per term sheet
B34: Euro term loan amortisation (% a year) | C34: 0 | D34: % | E34: Disclosed | F34: Term sheet: bullet at maturity
B35: Dollar term loan amortisation (% a year) | C35: 0.01 | D35: % | E35: Disclosed | F35: Term sheet: 0.25% a quarter on the USD tranche
B36: Excess cash used to prepay debt | C36: 0.5 | D36: % | E36: Estimate | F36: Typical excess cash flow sweep; voluntary prepayment assumption
B37: 2025E bridge (H1 actual + H2 estimate)
B38: Scientific: H2 2025 sales growth vs H2 2024 | C38: 0.04 | D38: % | E38: Estimate | F38: H1 2025 LFL +3%; acquisitions (SciAps, Micromeritics) annualised by H2
B39: Scientific: H2 2025 adjusted operating margin | C39: 0.235 | D39: % | E39: Estimate | F39: H2 2024 margin 22.8% plus programme savings
B40: Dynamics: H2 2025 sales growth vs H2 2024 | C40: -0.01 | D40: % | E40: Estimate | F40: H1 2025 LFL -3%
B41: Dynamics: H2 2025 adjusted operating margin | C41: 0.175 | D41: % | E41: Estimate | F41: H2 2024 margin 16.5% plus programme savings
B42: Group central costs 2025E | C42: 15 | D42: £m | E42: Estimate | F42: H1 2025 £8.5m (FY2024 £10.9m)
...

Sheet Historicals
B2: Historical and 2025E divisional financials (£m)
B3: Sources: FY2024 results (28 Feb 2025), H1 2025 results. H2 = full year less H1. 2025E = H1 2025 actual + H2 2025 estimate.
B5: £m | C5: FY2023A | D5: FY2024A | E5: H1 2024A | F5: H2 2024A | G5: H1 2025A | H5: H2 2025E | I5: FY2025E | J5: Note
B6: Spectris Scientific
B7: Sales | C7: 804.6 | D7: 776.7 | E7: 320 | F7: =D7-E7 -> 456.7 | G7: 386 | H7: =F7*(1+Sci_H2_G) -> 474.968 | I7: =G7+H7 -> 860.968
B8: Adjusted operating profit | C8: 171.9 | D8: 137.5 | E8: 33.4 | F8: =D8-E8 -> 104.1 | G8: 43 | H8: =H7*Sci_H2_M -> 111.61748 | I8: =G8+H8 -> 154.61748
B9: Margin | C9: =C8/C7 -> 0.21364653 | D9: =D8/D7 -> 0.17703103 | E9: =E8/E7 -> 0.104375 | F9: =F8/F7 -> 0.22793957 | G9: =G8/G7 -> 0.11139896 | H9: =H8/H7 -> 0.235 | I9: =I8/I7 -> 0.17958563 | J9: Strong H2 seasonality (year-end instrument budgets)
B10: Spectris Dynamics
B11: Sales | C11: 542.8 | D11: 501.7 | E11: 249.4 | F11: =D11-E11 -> 252.3 | G11: 250.1 | H11: =F11*(1+Dyn_H2_G) -> 249.777 | I11: =G11+H11 -> 499.877
B12: Adjusted operating profit | C12: 93 | D12: 72.3 | E12: 30.6 | F12: =D12-E12 -> 41.7 | G12: 31.1 | H12: =H11*Dyn_H2_M -> 43.710975 | I12: =G12+H12 -> 74.810975
B13: Margin | C13: =C12/C11 -> 0.17133382 | D13: =D12/D11 -> 0.14411003 | E13: =E12/E11 -> 0.12269447 | F13: =F12/F11 -> 0.16527943 | G13: =G12/G11 -> 0.12435026 | H13: =H12/H11 -> 0.175 | I13: =I12/I11 -> 0.14965877
B14: Group
B15: Red Lion Controls sales (sold Apr 2024) | C15: 101.8 | D15: 20.3 | E15: 20.3 | F15: =D15-E15 -> 0 | G15: 0 | H15: 0 | I15: =G15+H15 -> 0
B16: Red Lion Controls adjusted operating profit | D16: 3.7 | E16: 3.7 | F16: =D16-E16 -> 0 | G16: 0 | H16: 0 | I16: =G16+H16 -> 0
B17: Group central costs | D17: =D19-D8-D12-D16 -> -10.9 | E17: =E19-E8-E12-E16 -> -6.6 | F17: =D17-E17 -> -4.3 | G17: =G19-G8-G12-G16 -> -8.5 | H17: =-Costs_2025-G17 -> -6.5 | I17: =G17+H17 -> -15 | J17: FY2024 includes Spectris Foundation contribution
B18: Group sales | C18: 1449.2 | D18: =D7+D11+D15 -> 1298.7 | E18: =E7+E11+E15 -> 589.7 | F18: =F7+F11+F15 -> 709 | G18: =G7+G11+G15 -> 636.1 | H18: =H7+H11+H15 -> 724.745 | I18: =I7+I11+I15 -> 1360.845 | J18: FY2024 reported: 1,298.7
B19: Adjusted operating profit | C19: 262.5 | D19: 202.6 | E19: 61.1 | F19: =D19-E19 -> 141.5 | G19: 65.6 | H19: =H8+H12+H16+H17 -> 148.82845 | I19: =G19+H19 -> 214.42846
B20: Adjusted operating margin | C20: =C19/C18 -> 0.18113442 | D20: =D19/D18 -> 0.15600216 | E20: =E19/E18 -> 0.10361201 | F20: =F19/F18 -> 0.19957687 | G20: =G19/G18 -> 0.10312844 | H20: =H19/H18 -> 0.20535286 | I20: =I19/I18 -> 0.15757008
B21: Adjusted D&A (depreciation + software amortisation) | C21: 38.8 | D21: 36.1 | I21: =I18*DA_pct -> 38.10366
B22: Adjusted EBITDA | C22: =C19+C21 -> 301.3 | D22: =D19+D21 -> 238.7 | I22: =I19+I21 -> 252.53212 | J22: FY2024 matches the £239m in the Rule 2.7 announcement
B23: EBITDA margin | C23: =C22/C18 -> 0.20790781 | D23: =D22/D18 -> 0.18379918 | I23: =I22/I18 -> 0.18557008
B25: Other reported items
B26: Capex | C26: 24.7 | D26: 51.7 | G26: 21.1
B27: Net debt (cash) excl. leases | C27: -138.8 | D27: 549 | G27: 545.7
B28: Net debt / EBITDA | D28: =D27/D22 -> 2.2999581 | J28: Company reported 2.3x on a covenant basis
B30: Profit improvement programme: >£10m savings in H1 2025, >£30m in FY2025, >£50m run-rate by end 2026 (H1 2025 results).

Sheet Operating Model
B2: Operating model by division (£m)
B3: Divisional margins ramp in a straight line from 2025E to the 2030E inputs. Interest links to the Debt Schedule (opening balances, no circularity).
B5: £m | C5: 2025E | D5: 2026E | E5: 2027E | F5: 2028E | G5: 2029E | H5: 2030E
B6: Year index | C6: 0 | D6: 1 | E6: 2 | F6: 3 | G6: 4 | H6: 5
B7: Spectris Scientific
B8: Sales | C8: =Sci_Rev25 -> 860.968 | D8: =C8*(1+Sci_G) -> 916.93092 | E8: =D8*(1+Sci_G) -> 976.53143 | F8: =E8*(1+Sci_G) -> 1040.006 | G8: =F8*(1+Sci_G) -> 1107.6064 | H8: =G8*(1+Sci_G) -> 1179.6008
B9: Growth | C9: =C8/Historicals!D7-1 -> 0.10849491 | D9: =D8/C8-1 -> 0.065 | E9: =E8/D8-1 -> 0.065 | F9: =F8/E8-1 -> 0.065 | G9: =G8/F8-1 -> 0.065 | H9: =H8/G8-1 -> 0.065
B10: Adjusted operating margin | C10: =Sci_M25 -> 0.17958563 | D10: =$C10+(Sci_M_Exit-$C10)*D$6/Hold -> 0.1896685 | E10: =$C10+(Sci_M_Exit-$C10)*E$6/Hold -> 0.19975138 | F10: =$C10+(Sci_M_Exit-$C10)*F$6/Hold -> 0.20983425 | G10: =$C10+(Sci_M_Exit-$C10)*G$6/Hold -> 0.21991713 | H10: =$C10+(Sci_M_Exit-$C10)*H$6/Hold -> 0.23
B11: Adjusted operating profit | C11: =C8*C10 -> 154.61748 | D11: =D8*D10 -> 173.91292 | E11: =E8*E10 -> 195.0635 | F11: =F8*F10 -> 218.22888 | G11: =G8*G10 -> 243.58161 | H11: =H8*H10 -> 271.30818
B12: Spectris Dynamics
B13: Sales | C13: =Dyn_Rev25 -> 499.877 | D13: =C13*(1+Dyn_G) -> 522.37146 | E13: =D13*(1+Dyn_G) -> 545.87818 | F13: =E13*(1+Dyn_G) -> 570.4427 | G13: =F13*(1+Dyn_G) -> 596.11262 | H13: =G13*(1+Dyn_G) -> 622.93769
B14: Growth | C14: =C13/Historicals!D11-1 -> -0.0036336456 | D14: =D13/C13-1 -> 0.045 | E14: =E13/D13-1 -> 0.045 | F14: =F13/E13-1 -> 0.045 | G14: =G13/F13-1 -> 0.045 | H14: =H13/G13-1 -> 0.045
B15: Adjusted operating margin | C15: =Dyn_M25 -> 0.14965877 | D15: =$C15+(Dyn_M_Exit-$C15)*D$6/Hold -> 0.15772701 | E15: =$C15+(Dyn_M_Exit-$C15)*E$6/Hold -> 0.16579526 | F15: =$C15+(Dyn_M_Exit-$C15)*F$6/Hold -> 0.17386351 | G15: =$C15+(Dyn_M_Exit-$C15)*G$6/Hold -> 0.18193175 | H15: =$C15+(Dyn_M_Exit-$C15)*H$6/Hold -> 0.19
B16: Adjusted operating profit | C16: =C13*C15 -> 74.810975 | D16: =D13*D15 -> 82.392091 | E16: =E13*E15 -> 90.504015 | F16: =F13*F15 -> 99.179168 | G16: =G13*G15 -> 108.45181 | H16: =H13*H15 -> 118.35816
B17: Group
B18: Group sales | C18: =C8+C13 -> 1360.845 | D18: =D8+D13 -> 1439.3024 | E18: =E8+E13 -> 1522.4096 | F18: =F8+F13 -> 1610.4487 | G18: =G8+G13 -> 1703.719 | H18: =H8+H13 -> 1802.5385
B19: Growth | C19: =C18/Historicals!D18-1 -> 0.047851698 | D19: =D18/C18-1 -> 0.057653432 | E19: =E18/D18-1 -> 0.057741324 | F19: =F18/E18-1 -> 0.057828761 | G19: =G18/F18-1 -> 0.05791573 | H19: =H18/G18-1 -> 0.058002219
B20: Group central costs | C20: =-Costs_2025 -> -15 | D20: =C20*(1+Costs_G) -> -15.45 | E20: =D20*(1+Costs_G) -> -15.9135 | F20: =E20*(1+Costs_G) -> -16.390905 | G20: =F20*(1+Costs_G) -> -16.882632 | H20: =G20*(1+Costs_G) -> -17.389111
B21: Adjusted operating profit (EBIT) | C21: =C11+C16+C20 -> 214.42846 | D21: =D11+D16+D20 -> 240.85501 | E21: =E11+E16+E20 -> 269.65401 | F21: =F11+F16+F20 -> 301.01714 | G21: =G11+G16+G20 -> 335.15079 | H21: =H11+H16+H20 -> 372.27723
B22: Adjusted operating margin | C22: =C21/C18 -> 0.15757008 | D22: =D21/D18 -> 0.16734149 | E22: =E21/E18 -> 0.17712317 | F22: =F21/F18 -> 0.18691508 | G22: =G21/G18 -> 0.19671718 | H22: =H21/H18 -> 0.20652942
B23: Add: D&A | C23: =C18*DA_pct -> 38.10366 | D23: =D18*DA_pct -> 40.300467 | E23: =E18*DA_pct -> 42.627469 | F23: =F18*DA_pct -> 45.092563 | G23: =G18*DA_pct -> 47.704131 | H23: =H18*DA_pct -> 50.471077
B24: Adjusted EBITDA | C24: =C21+C23 -> 252.53212 | D24: =D21+D23 -> 281.15547 | E24: =E21+E23 -> 312.28148 | F24: =F21+F23 -> 346.1097 | G24: =G21+G23 -> 382.85492 | H24: =H21+H23 -> 422.7483
B25: EBITDA margin | C25: =C24/C18 -> 0.18557008 | D25: =D24/D18 -> 0.19534149 | E25: =E24/E18 -> 0.20512317 | F25: =F24/F18 -> 0.21491508 | G25: =G24/G18 -> 0.22471718 | H25: =H24/H18 -> 0.23452942
B26: Free cash flow
B27: Adjusted EBITDA | D27: =D24 -> 281.15547 | E27: =E24 -> 312.28148 | F27: =F24 -> 346.1097 | G27: =G24 -> 382.85492 | H27: =H24 -> 422.7483
B28: Less: capex | D28: =-D18*Capex_pct -> -43.179072 | E28: =-E18*Capex_pct -> -45.672288 | F28: =-F18*Capex_pct -> -48.31346 | G28: =-G18*Capex_pct -> -51.111569 | H28: =-H18*Capex_pct -> -54.076154
B29: Less: increase in working capital | D29: =-(D18-C18)*NWC_pct -> -11.768608 | E29: =-(E18-D18)*NWC_pct -> -12.466084 | F29: =-(F18-E18)*NWC_pct -> -13.205859 | G29: =-(G18-F18)*NWC_pct -> -13.990546 | H29: =-(H18-G18)*NWC_pct -> -14.822922
B30: Less: interest | D30: =-'Debt Schedule'!D30 -> -98.140047 | E30: =-'Debt Schedule'!E30 -> -94.88213 | F30: =-'Debt Schedule'!F30 -> -90.878575 | G30: =-'Debt Schedule'!G30 -> -86.052157 | H30: =-'Debt Schedule'!H30 -> -80.319195
B31: Less: cash taxes | D31: =-MAX(0,(D21+D30)*Tax) -> -35.67874 | E31: =-MAX(0,(E21+E30)*Tax) -> -43.692971 | F31: =-MAX(0,(F21+F30)*Tax) -> -52.534641 | G31: =-MAX(0,(G21+G30)*Tax) -> -62.274658 | H31: =-MAX(0,(H21+H30)*Tax) -> -72.989508
B32: Free cash flow available for debt service | D32: =SUM(D27:D31) -> 92.389007 | E32: =SUM(E27:E31) -> 115.56801 | F32: =SUM(F27:F31) -> 141.17717 | G32: =SUM(G27:G31) -> 169.42599 | H32: =SUM(H27:H31) -> 200.54053
B33: FCF / EBITDA | D33: =D32/D24 -> 0.32860469 | E33: =E32/E24 -> 0.37007641 | F33: =F32/F24 -> 0.40789717 | G33: =G32/G24 -> 0.44253314 | H33: =H32/H24 -> 0.47437334

Sheet Sources & Uses
B2: Sources and uses at completion (£m)
B3: Debt fixed at the disclosed term loans. Fees built from the published fee letter. Sponsor equity is the balancing item.
B5: Uses | C5: £m | D5: % total
B6: Cash paid to shareholders (£41.47 x shares) | C6: =(Price-Dividend)*Shares -> 4171.882 | D6: =C6/$C$12 -> 0.84166791
B7: Refinance Spectris gross borrowings | C7: =Gross_Debt -> 633.1 | D7: =C7/$C$12 -> 0.12772652
B8: Financing fees and OID (fee letter rates) | C8: =C13*(Fee_EUR+OID)+C14*(Fee_USD+OID)+RCF*Fee_RCF -> 50.842733 | D8: =C8/$C$12 -> 0.010257408
B9: Stamp duty (0.5%) | C9: =C6*Stamp -> 20.85941 | D9: =C9/$C$12 -> 0.0042083396
B10: Bidco advisory, legal and other costs | C10: =Advisory -> 45 | D10: =C10/$C$12 -> 0.0090786499
B11: Spectris transaction costs settled at close | C11: =Target_Costs -> 35 | D11: =C11/$C$12 -> 0.0070611721
B12: Total uses | C12: =SUM(C6:C11) -> 4956.6841 | D12: =C12/$C$12 -> 1
B13: Euro term loan B (€975m) | C13: =EUR_TL*EURGBP -> 848.25 | D13: =C13/$C$17 -> 0.17113255 | F13: Sources rows sit directly below uses so the fee formula can reference the sterling loan amounts.
B14: Dollar term loan B ($900m) | C14: =USD_TL/GBPUSD -> 671.64179 | D14: =C14/$C$17 -> 0.13550224
B15: Revolving credit facility (undrawn) | C15: 0 | D15: =C15/$C$17 -> 0
B16: Sponsor and co-investor equity (plug) | C16: =C12-SUM(C13:C15) -> 3436.7924 | D16: =C16/$C$17 -> 0.69336521
B17: Total sources | C17: =SUM(C13:C16) -> 4956.6841 | D17: =C17/$C$17 -> 1
B18: Check: sources less uses | C18: =C17-C12 -> 0
B20: Entry metrics
B21: Headline equity value (offer value x shares) | C21: =Price*Shares -> 4200.05
B22: Enterprise value (equity + Jun-25 net debt + leases) | C22: =C21+NetDebt_H1+Leases -> 4822.25
B23: EV / FY2024 EBITDA (disclosed: 20.3x) | C23: =C22/EBITDA_FY24 -> 20.176778
B24: EV / 2025E EBITDA | C24: =C22/EBITDA_25 -> 19.095591
B25: Term debt / FY2024 EBITDA | C25: =SUM(Debt0)/EBITDA_FY24 -> 6.3593799
B26: Term debt / 2025E EBITDA | C26: =SUM(Debt0)/EBITDA_25 -> 6.0186079
B27: Net debt at close (term debt less cash retained) | C27: =SUM(Debt0)-Cash_Close -> 1460.6918
B28: Equity as % of total capital | C28: =C16/(C16+SUM(Debt0)) -> 0.69336521
B29: Premium to undisturbed price | C29: =Price/Undisturbed-1 -> 1.048577
B30: EV at undisturbed price / FY2024 EBITDA | C30: =(Undisturbed*Shares+NetDebt_H1+Leases)/EBITDA_FY24 -> 11.181707
B32: Equity reconciliation: what explains the gap to the syndication notices?
B33: Item | C33: £m | F33: Basis
B34: Co-investor commitments, 5 Aug 2025 (Neuberger Berman, Pathway) | C34: 218.79872 | F34: Increased offer announcement: "approximately 5.80%" indirect economic interest
B35: Stated share of Bidco | C35: 0.058
B36: Implied total equity, Aug 2025 | C36: =C34/C35 -> 3772.3917
B37: Co-investor commitments, 14 Nov 2025 (incl. Temasek vehicle) | C37: 1042.9539 | F37: Update on financing and equity syndication: "up to" £1,042,953,850
B38: Stated maximum share of Bidco | C38: 0.2854 | F38: "maximum indirect economic interest ... up to approximately 28.54%"
B39: Implied total equity, Nov 2025 | C39: =C37/C38 -> 3654.3583
B40: Equity in this model | C40: =Equity0 -> 3436.7924 | F40: Sources and uses above
B41: Gap to Nov 2025 implied equity | C41: =C39-C40 -> 217.56592
B42: Fall in implied equity between Aug and Nov | C42: =C36-C39 -> 118.03347 | F42: Commitments are caps sized for certain funds, tightened as costs became known
B43: Ticking fees, allocation to close (term sheet) | C43: =SUM(Debt0)*Margin_TLB*0.5*10/365 -> 0.78076633 | F43: 50% of margin from day 61; ~10 days at 50% before 4 Dec close (estimate)
B44: Remaining unexplained | C44: =C41-C43 -> 216.78515
...

Sheet Debt Schedule
B2: Debt schedule (£m)
B3: Interest on opening balances. Mandatory amortisation, then a cash sweep applied pro rata; remaining cash builds on balance sheet.
B5: £m | C5: Close | D5: 2026E | E5: 2027E | F5: 2028E | G5: 2029E | H5: 2030E
B6: Cash available for debt repayment
B7: Free cash flow (Operating Model) | D7: ='Operating Model'!D32 -> 92.389007 | E7: ='Operating Model'!E32 -> 115.56801 | F7: ='Operating Model'!F32 -> 141.17717 | G7: ='Operating Model'!G32 -> 169.42599 | H7: ='Operating Model'!H32 -> 200.54053
B8: Less: mandatory amortisation | D8: =-(D14+D21) -> -6.7164179 | E8: =-(E14+E21) -> -6.7164179 | F8: =-(F14+F21) -> -6.7164179 | G8: =-(G14+G21) -> -6.7164179 | H8: =-(H14+H21) -> -6.7164179
B9: Cash after mandatory repayment | D9: =D7+D8 -> 85.672589 | E9: =E7+E8 -> 108.85159 | F9: =F7+F8 -> 134.46075 | G9: =G7+G8 -> 162.70957 | H9: =H7+H8 -> 193.82411
B10: Cash sweep applied | D10: =IF(D9>0,MIN(D9*Sweep,D15+D22),0) -> 42.836295 | E10: =IF(E9>0,MIN(E9*Sweep,E15+E22),0) -> 54.425796 | F10: =IF(F9>0,MIN(F9*Sweep,F15+F22),0) -> 67.230374 | G10: =IF(G9>0,MIN(G9*Sweep,G15+G22),0) -> 81.354786 | H10: =IF(H9>0,MIN(H9*Sweep,H15+H22),0) -> 96.912054
B11: Change in cash | D11: =D9-D10 -> 42.836295 | E11: =E9-E10 -> 54.425796 | F11: =F9-F10 -> 67.230374 | G11: =G9-G10 -> 81.354786 | H11: =H9-H10 -> 96.912054
B12: Euro term loan B (Euribor + margin, bullet)
B13: Opening balance | D13: =C17 -> 848.25 | E13: =D17 -> 824.237 | F13: =E17 -> 793.58719 | G13: =F17 -> 755.54519 | H13: =G17 -> 709.27822
B14: Mandatory amortisation | D14: =MIN(D13,$C$17*Amort_EUR) -> 0 | E14: =MIN(E13,$C$17*Amort_EUR) -> 0 | F14: =MIN(F13,$C$17*Amort_EUR) -> 0 | G14: =MIN(G13,$C$17*Amort_EUR) -> 0 | H14: =MIN(H13,$C$17*Amort_EUR) -> 0
B15: Balance after amortisation | D15: =D13-D14 -> 848.25 | E15: =E13-E14 -> 824.237 | F15: =F13-F14 -> 793.58719 | G15: =G13-G14 -> 755.54519 | H15: =H13-H14 -> 709.27822
B16: Sweep (pro rata) | D16: =IF((D15+D22)>0,D10*D15/(D15+D22),0) -> 24.013004 | E16: =IF((E15+E22)>0,E10*E15/(E15+E22),0) -> 30.649808 | F16: =IF((F15+F22)>0,F10*F15/(F15+F22),0) -> 38.042002 | G16: =IF((G15+G22)>0,G10*G15/(G15+G22),0) -> 46.266962 | H16: =IF((H15+H22)>0,H10*H15/(H15+H22),0) -> 55.41289
B17: Closing balance | C17: ='Sources & Uses'!C13 -> 848.25 | D17: =D15-D16 -> 824.237 | E17: =E15-E16 -> 793.58719 | F17: =F15-F16 -> 755.54519 | G17: =G15-G16 -> 709.27822 | H17: =H15-H16 -> 653.86533
B19: Dollar term loan B (SOFR + margin, 1% a year amortisation)
B20: Opening balance | D20: =C24 -> 671.64179 | E20: =D24 -> 646.10208 | F20: =E24 -> 615.60968 | G20: =F24 -> 579.70489 | H20: =G24 -> 537.90065
B21: Mandatory amortisation | D21: =MIN(D20,$C$24*Amort_USD) -> 6.7164179 | E21: =MIN(E20,$C$24*Amort_USD) -> 6.7164179 | F21: =MIN(F20,$C$24*Amort_USD) -> 6.7164179 | G21: =MIN(G20,$C$24*Amort_USD) -> 6.7164179 | H21: =MIN(H20,$C$24*Amort_USD) -> 6.7164179
B22: Balance after amortisation | D22: =D20-D21 -> 664.92537 | E22: =E20-E21 -> 639.38567 | F22: =F20-F21 -> 608.89326 | G22: =G20-G21 -> 572.98847 | H22: =H20-H21 -> 531.18423
B23: Sweep (pro rata) | D23: =D10-D16 -> 18.82329 | E23: =E10-E16 -> 23.775987 | F23: =F10-F16 -> 29.188372 | G23: =G10-G16 -> 35.087823 | H23: =H10-H16 -> 41.499164
B24: Closing balance | C24: ='Sources & Uses'!C14 -> 671.64179 | D24: =D22-D23 -> 646.10208 | E24: =E22-E23 -> 615.60968 | F24: =F22-F23 -> 579.70489 | G24: =G22-G23 -> 537.90065 | H24: =H22-H23 -> 489.68506
B26: Interest
B27: Euro all-in rate | D27: =Euribor+Margin_TLB -> 0.0575 | E27: =Euribor+Margin_TLB -> 0.0575 | F27: =Euribor+Margin_TLB -> 0.0575 | G27: =Euribor+Margin_TLB -> 0.0575 | H27: =Euribor+Margin_TLB -> 0.0575
B28: Euro term loan interest | D28: =D13*D27 -> 48.774375 | E28: =E13*E27 -> 47.393627 | F28: =F13*F27 -> 45.631263 | G28: =G13*G27 -> 43.443848 | H28: =H13*H27 -> 40.783498
B29: Dollar term loan interest (SOFR + margin) | D29: =D20*(SOFR+Margin_TLB) -> 49.365672 | E29: =E20*(SOFR+Margin_TLB) -> 47.488503 | F29: =F20*(SOFR+Margin_TLB) -> 45.247311 | G29: =G20*(SOFR+Margin_TLB) -> 42.608309 | H29: =H20*(SOFR+Margin_TLB) -> 39.535698
B30: Total interest | D30: =D28+D29 -> 98.140047 | E30: =E28+E29 -> 94.88213 | F30: =F28+F29 -> 90.878575 | G30: =G28+G29 -> 86.052157 | H30: =H28+H29 -> 80.319195
B32: Credit statistics
B33: Cash balance | C33: =Cash_Close -> 59.2 | D33: =C33+D11 -> 102.03629 | E33: =D33+E11 -> 156.46209 | F33: =E33+F11 -> 223.69246 | G33: =F33+G11 -> 305.04725 | H33: =G33+H11 -> 401.9593
B34: Gross term debt | C34: =C17+C24 -> 1519.8918 | D34: =D17+D24 -> 1470.3391 | E34: =E17+E24 -> 1409.1969 | F34: =F17+F24 -> 1335.2501 | G34: =G17+G24 -> 1247.1789 | H34: =H17+H24 -> 1143.5504
B35: Net debt (excl. leases) | C35: =C34-C33 -> 1460.6918 | D35: =D34-D33 -> 1368.3028 | E35: =E34-E33 -> 1252.7348 | F35: =F34-F33 -> 1111.5576 | G35: =G34-G33 -> 942.13162 | H35: =H34-H33 -> 741.59109
B36: Net debt / EBITDA | C36: =C35/'Operating Model'!C24 -> 5.7841823 | D36: =D35/'Operating Model'!D24 -> 4.8667123 | E36: =E35/'Operating Model'!E24 -> 4.0115564 | F36: =F35/'Operating Model'!F24 -> 3.211576 | G36: =G35/'Operating Model'!G24 -> 2.4608058 | H36: =H35/'Operating Model'!H24 -> 1.7542142
B37: EBITDA / interest | D37: ='Operating Model'!D24/D30 -> 2.8648394 | E37: ='Operating Model'!E24/E30 -> 3.2912571 | F37: ='Operating Model'!F24/F30 -> 3.8084851 | G37: ='Operating Model'!G24/G30 -> 4.4491031 | H37: ='Operating Model'!H24/H30 -> 5.2633533
B38: Cumulative term debt repaid | D38: =1-D34/$C$34 -> 0.03260279 | E38: =1-E34/$C$34 -> 0.072830794 | F38: =1-F34/$C$34 -> 0.12148346 | G38: =1-G34/$C$34 -> 0.17942917 | H38: =1-H34/$C$34 -> 0.24761065
B39: Margin ratchet test: net leverage <= 4.00x? | D39: =IF(D36<=4,"Ratchet","No") -> No | E39: =IF(E36<=4,"Ratchet","No") -> No | F39: =IF(F36<=4,"Ratchet","No") -> Ratchet | G39: =IF(G36<=4,"Ratchet","No") -> Ratchet | H39: =IF(H36<=4,"Ratchet","No") -> Ratchet
B41: Term sheet: margin steps down from 3.75% to 3.00% as leverage falls to 4.00x. Not modelled (conservative); the row above shows when it would apply.

Sheet Returns
B2: Returns analysis
B3: Exit at end of 2030E. No interim dividends. IRR from the annual cash flows; money multiple check alongside.
B5: Exit valuation (£m)
B6: 2030E adjusted EBITDA | C6: =EBITDA_Exit -> 422.7483
B7: Exit multiple | C7: =ExitMult -> 18
B8: Exit enterprise value | C8: =C6*C7 -> 7609.4695
B9: Less: net debt at exit | C9: =-ND_Exit -> -741.59109
B10: Less: lease liabilities | C10: =-Leases -> -76.5
B11: Exit equity value | C11: =SUM(C8:C10) -> 6791.3784
B12: Equity invested at completion | C12: =Equity0 -> 3436.7924
B13: Money multiple (MOIC) | C13: =C11/C12 -> 1.9760805
B14: IRR (cash flow basis) | C14: =IRR(C18:H18) -> 0.14593749
B15: IRR check: MOIC^(1/hold) - 1 | C15: =C13^(1/Hold)-1 -> 0.14593749
B17: Sponsor cash flows (£m) | C17: 2025E | D17: 2026E | E17: 2027E | F17: 2028E | G17: 2029E | H17: 2030E
B18: Equity in (-) / out (+) | C18: =-C12 -> -3436.7924 | D18: 0 | E18: 0 | F18: 0 | G18: 0 | H18: =C11 -> 6791.3784
B20: Value creation bridge (£m)
B21: EBITDA growth (valued at the entry multiple on 2025E) | C21: =(EBITDA_Exit-EBITDA_25)*EntryMult -> 3250.3788 | D21: =C21/$C$25 -> 0.96893587
B22: Multiple change (exit vs entry) | C22: =(ExitMult-EntryMult)*EBITDA_Exit -> -463.15927 | D22: =C22/$C$25 -> -0.13806749
B23: Debt paydown and cash build | C23: =ND_Close-ND_Exit -> 719.1007 | D23: =C23/$C$25 -> 0.21436347
B24: Transaction costs and other | C24: =C26-SUM(C21:C23) -> -151.73414 | D24: =C24/$C$25 -> -0.045231853 | F24: Residual equals fees and the cash/dividend timing differences between EV and uses.
B25: Total equity gain | C25: =SUM(C21:C24) -> 3354.586
B26: Exit equity less equity invested | C26: =C11-C12 -> 3354.586
B28: What has to be true to hit the hurdle
B29: Target IRR | C29: =Hurdle -> 0.18
B30: Exit equity needed | C30: =C12*(1+C29)^Hold -> 7862.5484
B31: Exit multiple needed (all else equal) | C31: =(C30+ND_Exit+Leases)/EBITDA_Exit -> 20.533824
B32: Equity cheque that hits the hurdle at the base exit | C32: =EqExit/(1+C29)^Hold -> 2968.5741
B33: Walk-away offer value per share | C33: =(C32+SUM(Debt0)-Gross_Debt-FinFees-Advisory-Target_Costs)/(Shares*(1+Stamp))+Dividend -> 37.118898
B34: Discount to KKR price | C34: =C33/Price-1 -> -0.11092459

Sheet Bid Comparison
B2: Bid comparison
B3: Same operating case and KKR's debt package at every price; each extra pound per share is funded with equity.
B5: Bid | C5: Date | D5: Offer value | E5: Premium | F5: EV (£m) | G5: EV / FY24 | H5: Equity (£m) | I5: MOIC | J5: IRR
B6: Advent original | C6: 23 Jun 2025 | D6: 37.63 | E6: =D6/Undisturbed-1 -> 0.84641806 | F6: =D6*Shares+NetDebt_H1+Leases -> 4407.778 | G6: =F6/EBITDA_FY24 -> 18.442586 | H6: =(D6-Dividend)*Shares*(1+Stamp)+Gross_Debt+FinFees+Advisory+Target_Costs-SUM(Debt0) -> 3020.248 | I6: =EqExit/H6 -> 2.2486161 | J6: =I6^(1/Hold)-1 -> 0.17593432
B7: KKR first offer | C7: 2 Jul 2025 | D7: 40 | E7: =D7/Undisturbed-1 -> 0.96270854 | F7: =D7*Shares+NetDebt_H1+Leases -> 4646.2 | G7: =F7/EBITDA_FY24 -> 19.440167 | H7: =(D7-Dividend)*Shares*(1+Stamp)+Gross_Debt+FinFees+Advisory+Target_Costs-SUM(Debt0) -> 3259.8621 | I7: =EqExit/H7 -> 2.083333 | J7: =I7^(1/Hold)-1 -> 0.15811514
B8: Advent increased | C8: 1 Aug 2025 | D8: 41 | E8: =D8/Undisturbed-1 -> 1.0117763 | F8: =D8*Shares+NetDebt_H1+Leases -> 4746.8 | G8: =F8/EBITDA_FY24 -> 19.861088 | H8: =(D8-Dividend)*Shares*(1+Stamp)+Gross_Debt+FinFees+Advisory+Target_Costs-SUM(Debt0) -> 3360.9651 | I8: =EqExit/H8 -> 2.0206632 | J8: =I8^(1/Hold)-1 -> 0.15106218
B9: KKR winning bid | C9: 5 Aug 2025 | D9: 41.75 | E9: =D9/Undisturbed-1 -> 1.048577 | F9: =D9*Shares+NetDebt_H1+Leases -> 4822.25 | G9: =F9/EBITDA_FY24 -> 20.176778 | H9: =(D9-Dividend)*Shares*(1+Stamp)+Gross_Debt+FinFees+Advisory+Target_Costs-SUM(Debt0) -> 3436.7924 | I9: =EqExit/H9 -> 1.9760805 | J9: =I9^(1/Hold)-1 -> 0.14593749
B11: IRR cost of winning vs Advent original | J11: =J6-J9 -> 0.02999683
B12: Extra equity vs Advent original (£m) | J12: =H9-H6 -> 416.54436
B14: Two financing strategies (from the published commitment letters)
B15: £m | C15: Advent | D15: KKR
B16: Senior term loan B | C16: 1750 | D16: =SUM(Debt0) -> 1519.8918 | F16: Advent: debt commitment letter to MI Metron Finance (Morgan Stanley, Barclays, HSBC): £1,750m Facility B,
B17: Second lien term loan | C17: 325 | D17: 0 | F17: £325m second lien, £325m RCF. KKR: €975m + $900m term loans and RCF (SFA, 30 Sep 2025).
B18: Revolving facility (undrawn) | C18: 325 | D18: =RCF -> 325
B19: Total term debt | C19: =C16+C17 -> 2075 | D19: =D16+D17 -> 1519.8918 | F19: Advent planned ~8.7x leverage with a second lien; KKR paid more but used ~6.4x senior-only debt.
B20: Term debt / FY2024 EBITDA | C20: =C19/EBITDA_FY24 -> 8.6820084 | D20: =D19/EBITDA_FY24 -> 6.3593799 | F20: Implied Advent equity uses KKR fee rates as a proxy. Advent fee letter: 1.75% EUR / 2.00% USD underwriting + 0.50% OID.
B21: Offer value per share | C21: =D6 -> 37.63 | D21: =D9 -> 41.75
B22: Implied equity cheque | C22: =(C21-Dividend)*Shares*(1+Stamp)+Gross_Debt+FinFees+Advisory+Target_Costs-C19 -> 2465.1398 | D22: =H9 -> 3436.7924

Sheet Comparables
B2: Comparables: support for the exit multiple
B3: Trading data from stockanalysis.com (LTM, as of the dates shown). Precedents from KPMG Test & Measurement review (Q2 2023) and the Spectris offer documents.
B5: Company | C5: Ticker | D5: Ccy | E5: EV (bn) | F5: LTM revenue (bn) | G5: EV / LTM EBITDA | H5: LTM EBITDA (bn) | I5: EBITDA margin | J5: Data as of
B6: Mettler-Toledo | C6: MTD | D6: USD | E6: 31.86 | F6: 4.13 | G6: 24.98 | H6: =E6/G6 -> 1.2754203 | I6: =H6/F6 -> 0.30881848 | J6: 2 Oct 2026
B7: Agilent Technologies | C7: A | D7: USD | E7: 49.69 | F7: 7.37 | G7: 23.89 | H7: =E7/G7 -> 2.0799498 | I7: =H7/F7 -> 0.28221842 | J7: 3 Oct 2026
B8: AMETEK | C8: AME | D8: USD | E8: 59.57 | F8: 7.86 | G8: 23.91 | H8: =E8/G8 -> 2.4914262 | I8: =H8/F8 -> 0.31697534 | J8: 2 Oct 2026
B9: Waters | C9: WAT | D9: USD | E9: 46.71 | F9: 4.64 | G9: 32.17 | H9: =E9/G9 -> 1.4519739 | I9: =H9/F9 -> 0.31292541 | J9: 3 Oct 2026
B10: Keysight Technologies | C10: KEYS | D10: USD | E10: 65.64 | F10: 6.58 | G10: 38.66 | H10: =E10/G10 -> 1.6978789 | I10: =H10/F10 -> 0.25803631 | J10: 2 Oct 2026
B11: Halma | C11: HLMA | D11: GBP | E11: 14.93 | F11: 2.58 | G11: 22.96 | H11: =E11/G11 -> 0.65026132 | I11: =H11/F11 -> 0.25203927 | J11: 8 Sep 2026
B12: Bruker | C12: BRKR | D12: USD | E12: 11.31 | F12: 3.5 | G12: 21.01 | H12: =E12/G12 -> 0.53831509 | I12: =H12/F12 -> 0.15380431 | J12: 2 Oct 2026
B13: Oxford Instruments | C13: OXIG | D13: GBP | E13: 1.5 | F13: 0.4232 | G13: 17.22 | H13: =E13/G13 -> 0.087108014 | I13: =H13/F13 -> 0.20583179 | J13: 29 Aug 2026
B15: Median, all peers | G15: =MEDIAN(G6:G13) -> 23.9 | I15: =MEDIAN(I6:I13) -> 0.27012737
B16: Median, peers with EBITDA margin above 24% | G16: =MEDIAN(G6:G11) -> 24.445
B17: Median, lower-margin peers (Bruker, Oxford Instruments) | G17: =MEDIAN(G12:G13) -> 19.115
B18: Spectris 2025E EBITDA margin (model) | I18: ='Operating Model'!C25 -> 0.18557008
B19: Spectris 2030E EBITDA margin (model) | I19: ='Operating Model'!H25 -> 0.23452942
B20: Keysight and Waters LTM multiples are inflated by recent acquisitions (Spirent; BD Biosciences) whose earnings are not yet fully in LTM EBITDA.
B21: EV and EV/EBITDA as reported by the data provider; LTM EBITDA and margin derived from them. Not adjusted to Spectris's EBITDA definition.
B23: Precedent transactions
B24: Target | C24: Acquirer | D24: Date | E24: EV | F24: Multiple basis | G24: EV / EBITDA | J24: Source
B25: National Instruments | C25: Emerson | D25: Apr 2023 | E25: $8.2bn | F25: 2023E EBITDA | G25: 15 | J25: KPMG T&M Q2 2023
B26: FLIR Systems | C26: Teledyne | D26: May 2021 | E26: $8.2bn | F26: LTM EBITDA | G26: 17.8 | J26: KPMG T&M Q2 2023
B27: OMEGA Engineering | C27: Arcline (PE) | D27: Jul 2022 | E27: $0.5bn | F27: LTM EBITDA | G27: 20.5 | J27: KPMG T&M Q2 2023
B28: Spectris | C28: Advent (original) | D28: Jun 2025 | E28: =TEXT('Bid Comparison'!F6/1000,"0.0")&"bn GBP" -> 4.4bn GBP | F28: FY2024 EBITDA | G28: ='Bid Comparison'!G6 -> 18.442586 | J28: Model, Advent price
B29: Spectris | C29: KKR (winning) | D29: Aug 2025 | E29: £4.8bn | F29: FY2024 EBITDA | G29: 20.3 | J29: KKR increased offer announcement
B30: Median of precedents | G30: =MEDIAN(G25:G29) -> 18.442586
B31: Sector trading: instrumentation, EV / 2023E EBITDA (Jun 2023) | G31: 19.5
B33: Exit multiple conclusion
B34: Base-case exit multiple | G34: =ExitMult -> 18
B35: Exit multiple needed for target IRR | G35: =Returns!C31 -> 20.533824
B36: Peers with 24-32% EBITDA margins trade at ~24x; Spectris-like margins (15-19%) trade at 17-21x. Precedents cluster at 15-20x.
B37: The base case (18.0x) assumes Spectris exits with margins near 23-24% but is still valued below premium peers. Paying 20.3x FY24 EBITDA
B38: and exiting at 18x builds in about two turns of multiple compression; a 20x+ exit needs Spectris to be re-rated alongside the high-margin group.

Sheet Sensitivities
B2: Sensitivity tables (IRR)
B3: Table 1 is fully live. Table 2 needs a full model re-run per cell, so its values are pasted from model runs.
B5: Table 1: IRR by offer value (rows) and exit multiple (columns). Live formulas.
B6: Offer value / exit multiple | C6: 15 | D6: 16.5 | E6: 18 | F6: 19.5 | G6: 21 | I6: IRR = ((2030E EBITDA x multiple - exit net debt - leases) / equity cheque)^(1/5) - 1.
B7: 37.63 | C7: =((EBITDA_Exit*C$6-ND_Exit-Leases)/(($B7-Dividend)*Shares*(1+Stamp)+Gross_Debt+FinFees+Advisory+Target_Costs-SUM(Debt0)))^(1/Hold)-1 -> 0.12831039 | D7: =((EBITDA_Exit*D$6-ND_Exit-Leases)/(($B7-Dividend)*Shares*(1+Stamp)+Gross_Debt+FinFees+Advisory+Target_Costs-SUM(Debt0)))^(1/Hold)-1 -> 0.15310517 | E7: =((EBITDA_Exit*E$6-ND_Exit-Leases)/(($B7-Dividend)*Shares*(1+Stamp)+Gross_Debt+FinFees+Advisory+Target_Costs-SUM(Debt0)))^(1/Hold)-1 -> 0.17593432 | F7: =((EBITDA_Exit*F$6-ND_Exit-Leases)/(($B7-Dividend)*Shares*(1+Stamp)+Gross_Debt+FinFees+Advisory+Target_Costs-SUM(Debt0)))^(1/Hold)-1 -> 0.19711709 | G7: =((EBITDA_Exit*G$6-ND_Exit-Leases)/(($B7-Dividend)*Shares*(1+Stamp)+Gross_Debt+FinFees+Advisory+Target_Costs-SUM(Debt0)))^(1/Hold)-1 -> 0.2168987 | I7: Exit net debt does not depend on price or exit multiple, so this grid is exact.
B8: 40 | C8: =((EBITDA_Exit*C$6-ND_Exit-Leases)/(($B8-Dividend)*Shares*(1+Stamp)+Gross_Debt+FinFees+Advisory+Target_Costs-SUM(Debt0)))^(1/Hold)-1 -> 0.11121287 | D8: =((EBITDA_Exit*D$6-ND_Exit-Leases)/(($B8-Dividend)*Shares*(1+Stamp)+Gross_Debt+FinFees+Advisory+Target_Costs-SUM(Debt0)))^(1/Hold)-1 -> 0.13563193 | E8: =((EBITDA_Exit*E$6-ND_Exit-Leases)/(($B8-Dividend)*Shares*(1+Stamp)+Gross_Debt+FinFees+Advisory+Target_Costs-SUM(Debt0)))^(1/Hold)-1 -> 0.15811514 | F8: =((EBITDA_Exit*F$6-ND_Exit-Leases)/(($B8-Dividend)*Shares*(1+Stamp)+Gross_Debt+FinFees+Advisory+Target_Costs-SUM(Debt0)))^(1/Hold)-1 -> 0.17897692 | G8: =((EBITDA_Exit*G$6-ND_Exit-Leases)/(($B8-Dividend)*Shares*(1+Stamp)+Gross_Debt+FinFees+Advisory+Target_Costs-SUM(Debt0)))^(1/Hold)-1 -> 0.19845878
B9: 41 | C9: =((EBITDA_Exit*C$6-ND_Exit-Leases)/(($B9-Dividend)*Shares*(1+Stamp)+Gross_Debt+FinFees+Advisory+Target_Costs-SUM(Debt0)))^(1/Hold)-1 -> 0.10444554 | D9: =((EBITDA_Exit*D$6-ND_Exit-Leases)/(($B9-Dividend)*Shares*(1+Stamp)+Gross_Debt+FinFees+Advisory+Target_Costs-SUM(Debt0)))^(1/Hold)-1 -> 0.12871589 | E9: =((EBITDA_Exit*E$6-ND_Exit-Leases)/(($B9-Dividend)*Shares*(1+Stamp)+Gross_Debt+FinFees+Advisory+Target_Costs-SUM(Debt0)))^(1/Hold)-1 -> 0.15106218 | F9: =((EBITDA_Exit*F$6-ND_Exit-Leases)/(($B9-Dividend)*Shares*(1+Stamp)+Gross_Debt+FinFees+Advisory+Target_Costs-SUM(Debt0)))^(1/Hold)-1 -> 0.17179691 | G9: =((EBITDA_Exit*G$6-ND_Exit-Leases)/(($B9-Dividend)*Shares*(1+Stamp)+Gross_Debt+FinFees+Advisory+Target_Costs-SUM(Debt0)))^(1/Hold)-1 -> 0.19116013
B10: 41.75 | C10: =((EBITDA_Exit*C$6-ND_Exit-Leases)/(($B10-Dividend)*Shares*(1+Stamp)+Gross_Debt+FinFees+Advisory+Target_Costs-SUM(Debt0)))^(1/Hold)-1 -> 0.099528394 | D10: =((EBITDA_Exit*D$6-ND_Exit-Leases)/(($B10-Dividend)*Shares*(1+Stamp)+Gross_Debt+FinFees+Advisory+Target_Costs-SUM(Debt0)))^(1/Hold)-1 -> 0.12369069 | E10: =((EBITDA_Exit*E$6-ND_Exit-Leases)/(($B10-Dividend)*Shares*(1+Stamp)+Gross_Debt+FinFees+Advisory+Target_Costs-SUM(Debt0)))^(1/Hold)-1 -> 0.14593749 | F10: =((EBITDA_Exit*F$6-ND_Exit-Leases)/(($B10-Dividend)*Shares*(1+Stamp)+Gross_Debt+FinFees+Advisory+Target_Costs-SUM(Debt0)))^(1/Hold)-1 -> 0.16657991 | G10: =((EBITDA_Exit*G$6-ND_Exit-Leases)/(($B10-Dividend)*Shares*(1+Stamp)+Gross_Debt+FinFees+Advisory+Target_Costs-SUM(Debt0)))^(1/Hold)-1 -> 0.18585691
B11: 43 | C11: =((EBITDA_Exit*C$6-ND_Exit-Leases)/(($B11-Dividend)*Shares*(1+Stamp)+Gross_Debt+FinFees+Advisory+Target_Costs-SUM(Debt0)))^(1/Hold)-1 -> 0.091615698 | D11: =((EBITDA_Exit*D$6-ND_Exit-Leases)/(($B11-Dividend)*Shares*(1+Stamp)+Gross_Debt+FinFees+Advisory+Target_Costs-SUM(Debt0)))^(1/Hold)-1 -> 0.11560411 | E11: =((EBITDA_Exit*E$6-ND_Exit-Leases)/(($B11-Dividend)*Shares*(1+Stamp)+Gross_Debt+FinFees+Advisory+Target_Costs-SUM(Debt0)))^(1/Hold)-1 -> 0.13769081 | F11: =((EBITDA_Exit*F$6-ND_Exit-Leases)/(($B11-Dividend)*Shares*(1+Stamp)+Gross_Debt+FinFees+Advisory+Target_Costs-SUM(Debt0)))^(1/Hold)-1 -> 0.15818468 | G11: =((EBITDA_Exit*G$6-ND_Exit-Leases)/(($B11-Dividend)*Shares*(1+Stamp)+Gross_Debt+FinFees+Advisory+Target_Costs-SUM(Debt0)))^(1/Hold)-1 -> 0.17732296
B13: Table 2: IRR by Scientific 2030E margin (rows) and Dynamics 2030E margin (columns). Pasted values.
B14: Scientific / Dynamics margin | C14: 0.16 | D14: 0.175 | E14: 0.19 | F14: 0.205 | G14: 0.22 | I14: Purple italic = pasted from model runs at base inputs. To make it live in Excel: put =Returns!C14 in B14,
B15: 0.2 | C15: 0.106536 | D15: 0.113764 | E15: 0.12081 | F15: 0.127682 | G15: 0.134391 | I15: select B14:G19, Data > What-If Analysis > Data Table; row input Inputs!C47, column input Inputs!C45.
B16: 0.215 | C16: 0.120034 | D16: 0.126925 | E16: 0.133652 | F16: 0.140223 | G16: 0.146646 | I16: Values match the model only while other inputs are at the base case.
B17: 0.23 | C17: 0.132911 | D17: 0.139499 | E17: 0.145937 | F17: 0.152235 | G17: 0.158397
B18: 0.245 | C18: 0.145228 | D18: 0.15154 | E18: 0.157718 | F18: 0.163766 | G18: 0.169691
B19: 0.26 | C19: 0.157036 | D19: 0.163099 | E19: 0.169037 | F19: 0.174857 | G19: 0.180564

Sheet Financing Terms
B2: Financing terms (KKR / Project Aurora)
B3: From the commitment letter term sheet, senior fee letter and RNS announcements published under Rule 26 of the Takeover Code.
B5: Term | C5: What the documents say | D5: Source and model treatment
B6: Facilities | C6: Interim: £1,500m term + £250m RCF (2 Jul 2025), RCF raised to £300m (5 Sep). Senior: €975m TLB, $900m TLB, £300m RCF (30 Sep), RCF £325m from 14 Nov 2025. | D6: Interim facilities agreement update; SFA RNS; equity syndication RNS. Modelled at €975m / $900m.
B7: Borrowers | C7: Project Aurora Holdco 1 Limited (parent); Project Aurora Bidco Limited and Project Aurora US Finco Inc. as borrowers. | D7: SFA RNS. US co-borrower allows a USD tranche placed with US investors.
B8: Margin | C8: Facility B 3.75% p.a.; RCF 3.00%. Leverage ratchet down to 3.00% (TLB) and 2.00% (RCF) at or below 4.00x. | D8: Commitment letter term sheet. Modelled at 3.75% flat (ratchet not applied).
B9: Base rate floor | C9: 0% on each facility. | D9: Term sheet.
B10: Maturity | C10: Facility B: 7 years from first utilisation. RCF: 6.5 years. | D10: Term sheet. Maturity ~Dec 2032, after a 2030 exit.
B11: Amortisation | C11: Bullet at maturity; USD tranche 0.25% per quarter. | D11: Term sheet. Modelled: EUR 0%, USD 1% a year.
B12: Financial covenant | C12: RCF only: net senior secured first lien leverage of 10.00:1, no step-downs, tested quarterly only if the RCF is drawn above 45%. | D12: Term sheet. Effectively covenant-lite for term lenders.
B13: Incremental debt | C13: Additional facilities up to 5.00x pro forma leverage, plus a free-and-clear amount of the greater of £300m and 100% of LTM EBITDA. | D13: Term sheet. Capacity for bolt-on M&A without new equity.
B14: Call protection | C14: Six-month 101 soft call on Facility B. | D14: Term sheet. Repricing possible early.
B15: Ticking fees | C15: 0% for 60 days after allocation; 50% of margin days 61-120; 100% thereafter. | D15: Term sheet. ~£1m estimated (Sources & Uses reconciliation).
B16: Underwriting fees and OID | C16: TLB: 1.75% (non-USD) and 2.25% (USD) of commitments; OID 1.00%; RCF 1.75%. Market flex caps redacted. | D16: Senior fee letter. Used to build financing fees in Sources & Uses.
... B20: Not disclosed | C20: Final syndicated pricing and OID; EBITDA add-back definitions and caps; MFN; liability-management blockers. | D20: The long-form SFA is not in the published set. Treated as unknown.

Sheet Checks
B2: Model integrity checks
B3: All checks should read OK.
B5: Check | C5: Value | D5: Result
B6: Sources equal uses | C6: ='Sources & Uses'!C18 -> 0 | D6: =IF(ABS(C6)<0.001,"OK","ERROR") -> OK
B7: Value bridge reconciles to equity gain | C7: =Returns!C25-Returns!C26 -> 0 | D7: =IF(ABS(C7)<0.001,"OK","ERROR") -> OK
B8: Cash-flow IRR equals MOIC-based IRR | C8: =Returns!C14-Returns!C15 -> 0 | D8: =IF(ABS(C8)<0.0001,"OK","ERROR") -> OK
B9: No negative debt balances | C9: =MIN('Debt Schedule'!C17:H17,'Debt Schedule'!C24:H24) -> 489.68506 | D9: =IF(C9>=-0.001,"OK","ERROR") -> OK
B10: Cash never negative | C10: =MIN('Debt Schedule'!C33:H33) -> 59.2 | D10: =IF(C10>=-0.001,"OK","CHECK") -> OK
B11: Sweep split adds up | C11: =SUM('Debt Schedule'!D16:H16)+SUM('Debt Schedule'!D23:H23)-SUM('Debt Schedule'!D10:H10) -> 0 | D11: =IF(ABS(C11)<0.001,"OK","ERROR") -> OK
B12: FY2024 EBITDA rebuild matches the £239m in the offer documents | C12: =Historicals!D22-EBITDA_FY24 -> -0.3 | D12: =IF(ABS(C12)<1,"OK","CHECK") -> OK
B13: FY2024 group sales rebuild matches reported £1,298.7m | C13: =Historicals!D18-1298.7 -> 0 | D13: =IF(ABS(C13)<0.1,"OK","CHECK") -> OK
B14: EV / FY24 EBITDA within 0.2x of the disclosed 20.3x | C14: ='Sources & Uses'!C23-20.3 -> -0.12322176 | D14: =IF(ABS(C14)<0.2,"OK","CHECK") -> OK
B16: Overall | D16: =IF(COUNTIF(D6:D14,"OK")=9,"ALL OK","REVIEW") -> ALL OK
